Workbook
Name Slicer_metode_pembayaran: #N/A
Name Slicer_tanggal: #N/A

Sheet 01_Pertanyaan
A1: Pertanyaan Bisnis
A2: 1. Menu terlaris
A3: Menu apa yang memiliki jumlah unit terjual paling banyak selama periode pengamatan? Tampilkan nama menu dan jumlah unit terjualnya.
A4: 2. Pendapatan minuman
A5: Berapa total pendapatan dari seluruh produk berkategori Minuman?
A6: 3. Rata-rata penjualan per transaksi
A7: Berapa rata-rata nilai penjualan setiap transaksi? Tentukan juga apakah rata-rata yang kamu gunakan adalah rata-rata nilai transaksi atau rata-rata unit terjual.

Sheet 02_Data_Kotor
A1: order_id | B1: tanggal | C1: nama_menu | D1: kategori | E1: harga_satuan | F1: jumlah_terjual | G1: metode_pembayaran
A2: ORD001 | B2: 46296 | C2: Americano | D2: Minuman | E2: 18000 | F2: 2 | G2: qris
A3: ORD002 | B3: 46296 | C3: Cappuccino | D3: minuman | E3: 25000 | F3: 1 | G3: Cash
A4: ORD003 | B4: 46296 | C4: latte | D4: Minuman | E4: 25000 | F4: 3 | G4: debit
A5: ORD004 | B5: 46296 | C5: croissant | D5: Makanan | E5: 20000 | F5: 2 | G5: QRIS
A6: ORD005 | B6: 46296 | C6: Matcha latte | D6: Minuman | E6: 28000 | F6: 2 | G6: Debit
A7: ORD006 | B7: 46297 | C7: Americano | D7: Minuman | E7: 18000 | F7: 4 | G7: Tunai
A8: ORD007 | B8: 46297 | C8: Chocolate Cake | D8: Makanan | E8: 22000 | F8: 1 | G8: QRIS
A9: ORD007 | B9: 46297 | C9: Chocolate Cake | D9: Makanan | E9: 22000 | F9: 1 | G9: QRIS
A10: ORD008 | B10: 46297 | C10: LATTE | D10: Minuman | E10: 25000 | F10: 2 | G10: QRIS
A11: ORD009 | B11: 46297 | C11: Chicken sandwich | D11: Makanan | E11: 32000 | F11: 2 | G11: DEBIT
A12: ORD010 | B12: 46297 | C12: es kopi susu | D12: Minuman | E12: 22000 | F12: 5 | G12: QRIS
A13: ORD011 | B13: 46298 | C13: Capuccino | D13: Minuman | E13: 25000 | F13: 2 | G13: Debit
A14: ORD012 | B14: 46298 | C14: Croissant | D14: MAKANAN | E14: 20000 | F14: 3 | G14: cash
A15: ORD013 | B15: 03/10/2026 | C15: americano | D15: Minuman | E15: 18000 | F15: 3 | G15: QRIS
A16: ORD014 | B16: 46298 | C16: matcha latte | D16: Minuman | E16: 28000 | F16: 1 | G16: Tunai
A17: ORD015 | B17: 46298 | C17: Chicken Sandwich | D17: Makanan | E17: 32000 | F17: 1 | G17: QRIS
A18: ORD016 | B18: 46299 | C18: Latte | D18: Minuman | E18: 25000 | F18: 4 | G18: QRIS
A19: ORD017 | B19: 46299 | C19: Es Kopi Susu | D19: Minuman | E19: 22000 | F19: 3 | G19: Debit
A20: ORD018 | B20: 46299 | C20: Chocolate Cake | D20: Makanan | E20: 22000 | F20: dua | G20: Tunai
A21: ORD019 | B21: 46299 | C21: Americano | D21: Minuman | E21: 18000 | F21: 2 | G21: Debit
A22: ORD020 | B22: 04 Okt 2026 | C22: Matcha Latte | D22: Minuman | E22: 28000 | F22: 2 | G22: QRIS
A23: ORD021 | B23: 46300 | C23: Cappucino | D23: Minuman | E23: 25000 | F23: 3 | G23: QRIS
A24: ORD022 | B24: 46300 | C24: Croissant | D24: Makanan | E24: 20000 | F24: 2 | G24: Kartu Debit
A25: ORD023 | B25: 46300 | C25: Latte | D25: Minuman | E25: 25000 | F25: 2 | G25: Tunai
A26: ORD024 | B26: 46300 | C26: Chicken Sandwich | D26: Makanan | E26: Rp32.000 | F26: 3 | G26: QRIS
A27: ORD023 | B27: 46300 | C27: Latte | D27: Minuman | E27: 25000 | F27: 2 | G27: Tunai
A28: ORD025 | B28: 46300 | C28: Es Kopi Susu | D28: minuman | E28: 22000 | F28: 4 | G28: Debit
A29: ORD026 | B29: 46301 | C29: Americano | D29: Minuman | E29: 18000 | F29: 3 pcs | G29: QRIS
A30: ORD027 | B30: 46301 | C30: Choco Cake | D30: Makanan | E30: 22000 | F30: 2 | G30: Debit
A31: ORD028 | B31: 46301 | C31: Matcha Latte | D31: Minuman | E31: 28000 | F31: 3 | G31: Tunai
A32: ORD029 | B32: 46301 | C32: Latte | D32: Minuman | F32: 1 | G32: QRIS
A33: ORD030 | B33: 46301 | C33: Croissant | D33: Makanan | E33: 20000 | F33: 4 | G33: Tunai
A34: ord031 | B34: 46302 | C34: Es Kopi Susu | D34: Minuman | E34: Rp 22.000 | F34: 6 | G34: QRIS
A35: ORD032 | B35: 2026-10-07 | C35: Cappuccino | D35: Minuman | E35: 25000 | F35: 2 | G35: Debit
A36: ORD033 | B36: 46302 | C36: Chicken Sandwich | D36: makanan | E36: 32000 | F36: 2 | G36: Tunai
A37: ORD034 | B37: 46302 | C37: Americano | D37: Minuman | E37: 18000 | F37: satu | G37: QRIS
A38: ORD035 | B38: 46302 | C38: Matcha Latte | D38: Minuman | E38: 28000 | F38: 2 | G38: debit card
A39: ORD036 | B39: 46303 | C39: Latte | D39: Minuman | E39: 25.000 | F39: 3 | G39: QRIS
A40: ORD037 | B40: 46303 | C40: Croissant | D40: Makanan | E40: 20000 | F40: 1 | G40: tunai
...

Sheet 02b_Log_Cleaning
A1: LOG CLEANING - DATA PENJUALAN KEDAI KOPI "DUMMY"
A3: A. Rekonsiliasi Jumlah Baris
A4: Keterangan | B4: Jumlah
A5: Baris data kotor | B5: =COUNTA('02_Data_Kotor'!A2:A54) -> 53
A6: Baris duplikat dihapus | B6: 3
A7: Baris data bersih (sesuai Table_Penjualan) | B7: =B5-B6 -> 50
A9: B. Daftar Masalah dan Tindakan
A10: No | B10: Kolom | C10: Masalah | D10: Jumlah | E10: sebelum -> sesudah | F10: Tindakan | G10: Alat Excel | H10: Dasar Keputusan
A11: 1 | B11: order_id | C11: Huruf kecil dan spasi di akhir | D11: 2 sel | E11: ord031 -> ORD031; "ORD028" -> ORD028 | F11: Hapus spasi, ubah ke huruf besar. Dikerjakan PERTAMA agar duplikat terdeteksi. | G11: TRIM, UPPER | H11: ID harus seragam sebelum dipakai sebagai kunci duplikat.
A12: 2 | B12: Semua kolom | C12: Baris duplikat persis | D12: 3 baris | E12: ORD007, ORD023, ORD045 muncul 2 kali | F12: Hapus kemunculan kedua, simpan yang pertama. | G12: Remove Duplicates | H12: order_id sama dan seluruh kolom identik, jadi merupakan pencatatan ganda. Dibuktikan setelah order_id dirapikan.
A13: 3 | B13: tanggal | C13: Tersimpan sebagai teks dengan format berbeda | D13: 3 sel | E13: 03/10/2026; 04 Okt 2026; 2026-10-07 -> tanggal sebenarnya | F13: Ubah ke format tanggal dd/mm/yyyy. | G13: DATEVALUE, Text to Columns, Find & Replace (Okt -> Oct) | H13: Format dd/mm/yyyy mengikuti kebiasaan Indonesia dan cocok dengan tanggal order di sekitarnya (urut per hari).
A14: 4 | B14: tanggal | C14: Kosong | D14: 1 sel | E14: ORD043: (kosong) -> 09/10/2026 | F14: Isi dengan tanggal baris sebelum dan sesudahnya. | G14: Isi manual / rumus | H14: Order tercatat urut; ORD042 dan ORD044 sama-sama 09/10/2026, sehingga ORD043 pasti di hari yang sama.
A15: 5 | B15: nama_menu | C15: Huruf besar/kecil, spasi, typo, dan alias | D15: 16 sel | E15: latte, LATTE -> Latte; Capuccino -> Cappuccino; Choco Cake -> Chocolate Cake | F15: Rapikan spasi dan huruf, lalu samakan alias lewat kamus (bagian C). | G15: TRIM, PROPER, Find & Replace | H15: Daftar menu baku ada 8 item. Alias dipetakan ke menu yang jelas harga dan kategorinya sama.
A16: 6 | B16: kategori | C16: Huruf besar/kecil dan spasi di akhir | D16: 7 sel | E16: MAKANAN -> Makanan; "Minuman " -> Minuman | F16: Hapus spasi dan samakan huruf. | G16: TRIM, PROPER | H16: Hanya ada 2 kategori baku: Makanan dan Minuman.
A17: 7 | B17: harga_satuan | C17: Tersimpan sebagai teks atau berformat Rp/titik/koma | D17: 6 sel | E17: Rp32.000 -> 32000; 25.000 -> 25000; 22,000 -> 22000 | F17: Buang "Rp", spasi, titik, koma, lalu ubah ke angka. | G17: SUBSTITUTE, VALUE | H17: Harga dalam Rupiah utuh tanpa desimal; titik/koma di sini pemisah ribuan.
A18: 8 | B18: harga_satuan | C18: Kosong | D18: 2 sel | E18: ORD029 (Latte) -> 25000; ORD044 (Matcha Latte) -> 28000 | F18: Isi dengan harga menu yang sama di baris lain. | G18: INDEX-MATCH / VLOOKUP | H18: Setiap menu punya satu harga tetap di seluruh data, jadi aman dipulihkan.
A19: 9 | B19: jumlah_terjual | C19: Berupa teks atau kata | D19: 4 sel | E19: "3 pcs" -> 3; "2" -> 2; dua -> 2; satu -> 1 | F19: Buang teks satuan, ubah kata menjadi angka, ubah ke bilangan. | G19: SUBSTITUTE, VALUE, Find & Replace | H19: Kata bilangan dan satuan jelas maknanya, sehingga dapat diterjemahkan tanpa menebak.
A20: 10 | B20: jumlah_terjual | C20: Outlier | D20: 1 sel | E20: ORD038: 40 -> 4 | F20: Koreksi menjadi 4 dan tandai sebagai ASUMSI. | G20: Filter / Conditional Formatting, lalu edit manual | H20: 49 order lain berkisar 1-6 unit; 40 paling mungkin salah ketik (angka 0 berlebih). Jika ragu, konfirmasi ke kasir.
A21: 11 | B21: metode_pembayaran | C21: Variasi penulisan | D21: 10 sel | E21: qris, QR Code -> QRIS; Cash, cash -> Tunai; debit, Kartu Debit, debit card -> Debit | F21: Samakan ke 3 nilai baku: QRIS, Tunai, Debit lewat kamus (bagian C). | G21: TRIM, PROPER, Find & Replace | H21: Hanya ada 3 metode bayar; semua variasi punya makna yang sama.
A23: C. Nilai Kotor -> Nilai Baku
A24: Kolom | B24: Nilai Kotor | C24: Nilai Baku
A25: nama_menu | B25: Capuccino | C25: Cappuccino
A26: nama_menu | B26: Cappucino | C26: Cappuccino
A27: nama_menu | B27: Choco Cake | C27: Chocolate Cake
A28: metode_pembayaran | B28: qris / QRIS | C28: QRIS
A29: metode_pembayaran | B29: QR Code | C29: QRIS
A30: metode_pembayaran | B30: Cash / cash / tunai | C30: Tunai
A31: metode_pembayaran | B31: debit / DEBIT | C31: Debit
A32: metode_pembayaran | B32: Kartu Debit | C32: Debit
A33: metode_pembayaran | B33: debit card | C33: Debit
A34: jumlah_terjual | B34: satu | C34: 1
A35: jumlah_terjual | B35: dua | C35: 2
A37: D. Urutan Pengerjaan yang Disarankan
A38: 1 | B38: Salin 02_Data_Kotor ke area kerja baru (jangan timpa data mentah).
A39: 2 | B39: Rapikan order_id (TRIM, UPPER).
A40: 3 | B40: Hapus duplikat (Remove Duplicates pada seluruh kolom) -> 53 menjadi 50 baris.
A41: 4 | B41: Rapikan nama_menu dan kategori (TRIM, PROPER), lalu terapkan kamus alias.
A42: 5 | B42: Samakan metode_pembayaran memakai kamus.
A43: 6 | B43: Ubah tanggal teks ke format tanggal; isi tanggal kosong dari baris tetangga.
A44: 7 | B44: Bersihkan harga_satuan (angka), lalu isi yang kosong dari harga menu yang sama.
...

Sheet 03_Data Bersih + Analisis
A1: TABEL PENJUALAN KEDAI KOPI "DUMMY"
J2: Statistik Nilai Transaksi per Kategori | N2: Statistik Nilai Transaksi Keseluruhan
A3: order_id | B3: tanggal | C3: nama_menu | D3: kategori | E3: harga_satuan | F3: jumlah_terjual | G3: metode_pembayaran | H3: nilai_transaksi | J3: Kategori | K3: Makanan | L3: Minuman | N3: Kategori | O3: Nilai Transaksi
A4: ORD001 | B4: 46296 | C4: Americano | D4: Minuman | E4: 18000 | F4: 2 | G4: QRIS | H4: =E4*F4 -> 36000 | J4: Minimum | K4: =_xlfn.MINIFS(H4:H53, D4:D53, "Makanan") -> 20000 | L4: =_xlfn.MINIFS(H4:H53,D4:D53,"minuman") -> 18000 | N4: Minimum | O4: =MIN(H4:H53) -> 18000
A5: ORD002 | B5: 46296 | C5: Cappuccino | D5: Minuman | E5: 25000 | F5: 1 | G5: Tunai | H5: =E5*F5 -> 25000 | J5: Maksimum | K5: =_xlfn.MAXIFS(H4:H53, D4:D53, "Makanan") -> 96000 | L5: =_xlfn.MAXIFS(H4:H53,D4:D53,"minuman") -> 132000 | N5: Maksimum | O5: =MAX(H4:H53) -> 132000
A6: ORD003 | B6: 46296 | C6: Latte | D6: Minuman | E6: 25000 | F6: 3 | G6: Debit | H6: =E6*F6 -> 75000 | J6: Rata-Rata (AVERAGEIFS) | K6: =AVERAGEIFS(H4:H53, D4:D53, "Makanan") -> 47875 | L6: =AVERAGEIFS(H4:H53, D4:D53, "Minuman") -> 62117.647 | N6: Rata-rata | O6: =AVERAGE(H4:H53) -> 57560
A7: ORD004 | B7: 46296 | C7: Croissant | D7: Makanan | E7: 20000 | F7: 2 | G7: QRIS | H7: =E7*F7 -> 40000 | J7: Rata-Rata (SUMIF/COUNTIF) | K7: =SUMIF(D4:D53, "Makanan", H4:H53) / COUNTIF(D4:D53, "Makanan") -> 47875 | L7: =SUMIF(D4:D53, "Minuman", H4:H53) / COUNTIF(D4:D53, "Minuman") -> 62117.647
A8: ORD005 | B8: 46296 | C8: Matcha Latte | D8: Minuman | E8: 28000 | F8: 2 | G8: Debit | H8: =E8*F8 -> 56000 | J8: Total | K8: =SUMIF(D4:D53, "Makanan", H4:H53) -> 766000 | L8: =SUMIF(D4:D53, "Minuman", H4:H53) -> 2112000
A9: ORD006 | B9: 46297 | C9: Americano | D9: Minuman | E9: 18000 | F9: 4 | G9: Tunai | H9: =E9*F9 -> 72000 | N9: Statistik Kuantitas per Transaksi
A10: ORD007 | B10: 46297 | C10: Chocolate Cake | D10: Makanan | E10: 22000 | F10: 1 | G10: QRIS | H10: =E10*F10 -> 22000 | J10: Rekapitulasi Total Unit Terjual per Menu | N10: Kategori | O10: Nilai Unit
A11: ORD008 | B11: 46297 | C11: Latte | D11: Minuman | E11: 25000 | F11: 2 | G11: QRIS | H11: =E11*F11 -> 50000 | J11: Nama Menu | K11: Total Unit | L11: Menu Terlaris | N11: Maksimal (Unit) | O11: =MAX(F4:F53) -> 6
A12: ORD009 | B12: 46297 | C12: Chicken Sandwich | D12: Makanan | E12: 32000 | F12: 2 | G12: Debit | H12: =E12*F12 -> 64000 | J12: {=_xlfn.UNIQUE(Table_Penjualan[nama_menu])} -> Americano | K12: {=SUMPRODUCT(($C$4:$C$53=$J12)*$F$4:$F$53)} -> 20 | L12: =IF(K12=MAX($K$12:$K$19), J12, "") | N12: Minimal (Unit) | O12: =MIN(F4:F53) -> 1
A13: ORD010 | B13: 46297 | C13: Es Kopi Susu | D13: Minuman | E13: 22000 | F13: 5 | G13: QRIS | H13: =E13*F13 -> 110000 | J13: Cappuccino | K13: {=SUMPRODUCT(($C$4:$C$53=$J13)*$F$4:$F$53)} -> 13 | L13: =IF(K13=MAX($K$12:$K$19), J13, "") | N13: Rata-Rata (Unit | O13: =AVERAGE(F4:F53) -> 2.48
A14: ORD011 | B14: 46298 | C14: Cappuccino | D14: Minuman | E14: 25000 | F14: 2 | G14: Debit | H14: =E14*F14 -> 50000 | J14: Latte | K14: {=SUMPRODUCT(($C$4:$C$53=$J14)*$F$4:$F$53)} -> 19 | L14: =IF(K14=MAX($K$12:$K$19), J14, "")
A15: ORD012 | B15: 46298 | C15: Croissant | D15: Makanan | E15: 20000 | F15: 3 | G15: Tunai | H15: =E15*F15 -> 60000 | J15: Croissant | K15: {=SUMPRODUCT(($C$4:$C$53=$J15)*$F$4:$F$53)} -> 14 | L15: =IF(K15=MAX($K$12:$K$19), J15, "")
A16: ORD013 | B16: 46298 | C16: Americano | D16: Minuman | E16: 18000 | F16: 3 | G16: QRIS | H16: =E16*F16 -> 54000 | J16: Matcha Latte | K16: {=SUMPRODUCT(($C$4:$C$53=$J16)*$F$4:$F$53)} -> 12 | L16: =IF(K16=MAX($K$12:$K$19), J16, "")
A17: ORD014 | B17: 46298 | C17: Matcha Latte | D17: Minuman | E17: 28000 | F17: 1 | G17: Tunai | H17: =E17*F17 -> 28000 | J17: Chocolate Cake | K17: {=SUMPRODUCT(($C$4:$C$53=$J17)*$F$4:$F$53)} -> 9 | L17: =IF(K17=MAX($K$12:$K$19), J17, "")
A18: ORD015 | B18: 46298 | C18: Chicken Sandwich | D18: Makanan | E18: 32000 | F18: 1 | G18: QRIS | H18: =E18*F18 -> 32000 | J18: Chicken Sandwich | K18: {=SUMPRODUCT(($C$4:$C$53=$J18)*$F$4:$F$53)} -> 9 | L18: =IF(K18=MAX($K$12:$K$19), J18, "")
A19: ORD016 | B19: 46299 | C19: Latte | D19: Minuman | E19: 25000 | F19: 4 | G19: QRIS | H19: =E19*F19 -> 100000 | J19: Es Kopi Susu | K19: {=SUMPRODUCT(($C$4:$C$53=$J19)*$F$4:$F$53)} -> 28 | L19: =IF(K19=MAX($K$12:$K$19), J19, "") -> Es Kopi Susu
A20: ORD017 | B20: 46299 | C20: Es Kopi Susu | D20: Minuman | E20: 22000 | F20: 3 | G20: Debit | H20: =E20*F20 -> 66000
A21: ORD018 | B21: 46299 | C21: Chocolate Cake | D21: Makanan | E21: 22000 | F21: 2 | G21: Tunai | H21: =E21*F21 -> 44000 | J21: Ringkasan
A22: ORD019 | B22: 46299 | C22: Americano | D22: Minuman | E22: 18000 | F22: 2 | G22: Debit | H22: =E22*F22 -> 36000 | J22: Nama Menu | K22: Total Unit
A23: ORD020 | B23: 46299 | C23: Matcha Latte | D23: Minuman | E23: 28000 | F23: 2 | G23: QRIS | H23: =E23*F23 -> 56000 | J23: Croissant | K23: =SUMIF($J$12:$J$19, J23, $K$12:$K$19) -> 14
A24: ORD021 | B24: 46300 | C24: Cappuccino | D24: Minuman | E24: 25000 | F24: 3 | G24: QRIS | H24: =E24*F24 -> 75000
A25: ORD022 | B25: 46300 | C25: Croissant | D25: Makanan | E25: 20000 | F25: 2 | G25: Debit | H25: =E25*F25 -> 40000 | J25: Penjualan Unit Tertinggi | K25: =MAX(K12:K19) -> 28
A26: ORD023 | B26: 46300 | C26: Latte | D26: Minuman | E26: 25000 | F26: 2 | G26: Tunai | H26: =E26*F26 -> 50000 | J26: Penjualan Unit Terendah | K26: =MIN(K12:K19) -> 9
A27: ORD024 | B27: 46300 | C27: Chicken Sandwich | D27: Makanan | E27: 32000 | F27: 3 | G27: QRIS | H27: =E27*F27 -> 96000 | J27: Penjualan Unit Rata-Rata | K27: =AVERAGE(K12:K19) -> 15.5
A28: ORD025 | B28: 46300 | C28: Es Kopi Susu | D28: Minuman | E28: 22000 | F28: 4 | G28: Debit | H28: =E28*F28 -> 88000
A29: ORD026 | B29: 46301 | C29: Americano | D29: Minuman | E29: 18000 | F29: 3 | G29: QRIS | H29: =E29*F29 -> 54000
A30: ORD027 | B30: 46301 | C30: Chocolate Cake | D30: Makanan | E30: 22000 | F30: 2 | G30: Debit | H30: =E30*F30 -> 44000 | J30: Total Pendapatan (Slicer) | K30: =IFERROR(GETPIVOTDATA("Sum of nilai_transaksi",'04_Pivot_Table'!$D$1),0) -> 2878000
A31: ORD028 | B31: 46301 | C31: Matcha Latte | D31: Minuman | E31: 28000 | F31: 3 | G31: Tunai | H31: =E31*F31 -> 84000 | J31: Jumlah Transaksi (Slicer) | K31: =IFERROR(GETPIVOTDATA("Count of order_id",'04_Pivot_Table'!$J$4),0) -> 50
A32: ORD029 | B32: 46301 | C32: Latte | D32: Minuman | E32: 25000 | F32: 1 | G32: QRIS | H32: =E32*F32 -> 25000 | J32: Item Terjual (Slicer) | K32: =IFERROR(GETPIVOTDATA("Sum of jumlah_terjual",'04_Pivot_Table'!$A$1),0) -> 124
A33: ORD030 | B33: 46301 | C33: Croissant | D33: Makanan | E33: 20000 | F33: 4 | G33: Tunai | H33: =E33*F33 -> 80000 | J33: Rata-Rata per Transaksi (Slicer) | K33: =IFERROR(GETPIVOTDATA("Average of nilai_transaksi",'04_Pivot_Table'!$G$1),0) -> 57560
A34: ORD031 | B34: 46302 | C34: Es Kopi Susu | D34: Minuman | E34: 22000 | F34: 6 | G34: QRIS | H34: =E34*F34 -> 132000
A35: ORD032 | B35: 46302 | C35: Cappuccino | D35: Minuman | E35: 25000 | F35: 2 | G35: Debit | H35: =E35*F35 -> 50000
A36: ORD033 | B36: 46302 | C36: Chicken Sandwich | D36: Makanan | E36: 32000 | F36: 2 | G36: Tunai | H36: =E36*F36 -> 64000
A37: ORD034 | B37: 46302 | C37: Americano | D37: Minuman | E37: 18000 | F37: 1 | G37: QRIS | H37: =E37*F37 -> 18000
A38: ORD035 | B38: 46302 | C38: Matcha Latte | D38: Minuman | E38: 28000 | F38: 2 | G38: Debit | H38: =E38*F38 -> 56000
A39: ORD036 | B39: 46303 | C39: Latte | D39: Minuman | E39: 25000 | F39: 3 | G39: QRIS | H39: =E39*F39 -> 75000
A40: ORD037 | B40: 46303 | C40: Croissant | D40: Makanan | E40: 20000 | F40: 1 | G40: Tunai | H40: =E40*F40 -> 20000
...

Sheet 04_Pivot_Table
A1: Row Labels | B1: Sum of jumlah_terjual | D1: Row Labels | E1: Sum of nilai_transaksi | G1: Row Labels | H1: Average of nilai_transaksi
A2: Chocolate Cake | B2: 9 | D2: Makanan | E2: 766000 | G2: Makanan | H2: 47875
A3: Chicken Sandwich | B3: 9 | D3: Minuman | E3: 2112000 | G3: Minuman | H3: 62117.647
A4: Matcha Latte | B4: 12 | D4: Grand Total | E4: 2878000 | G4: Grand Total | H4: 57560 | J4: Row Labels | K4: Count of order_id
A5: Cappuccino | B5: 13 | J5: Debit | K5: 15
A6: Croissant | B6: 14 | J6: QRIS | K6: 22
A7: Latte | B7: 19 | D7: Row Labels | E7: Sum of jumlah_terjual | G7: Row Labels | H7: Average of jumlah_terjual | J7: Tunai | K7: 13
A8: Americano | B8: 20 | D8: Makanan | E8: 32 | G8: Makanan | H8: 2 | J8: Grand Total | K8: 50
A9: Es Kopi Susu | B9: 28 | D9: Minuman | E9: 92 | G9: Minuman | H9: 2.7058824
A10: Grand Total | B10: 124 | D10: Grand Total | E10: 124 | G10: Grand Total | H10: 2.48
A13: Row Labels | B13: Sum of nilai_transaksi | D13: Row Labels | E13: Sum of nilai_transaksi
A14: 46296 | B14: 232000 | D14: Chocolate Cake | E14: 198000
A15: 46297 | B15: 318000 | D15: Croissant | E15: 280000
A16: 46298 | B16: 224000 | D16: Chicken Sandwich | E16: 288000
A17: 46299 | B17: 302000 | D17: Cappuccino | E17: 325000
A18: 46300 | B18: 349000 | D18: Matcha Latte | E18: 336000
A19: 46301 | B19: 287000 | D19: Americano | E19: 360000
A20: 46302 | B20: 320000 | D20: Latte | E20: 475000
A21: 46303 | B21: 274000 | D21: Es Kopi Susu | E21: 616000
A22: 46304 | B22: 294000 | D22: Grand Total | E22: 2878000
A23: 46305 | B23: 278000
A24: Grand Total | B24: 2878000

Sheet 05_Dashboard
B1: DASHBOARD PENJUALAN KEDAI KOPI "DUMMY"

Sheet 06_Jawaban + Rekomendasi
A1: JAWABAN
A3: No | B3: Pertanyaan Bisnis | C3: Jawaban
A4: 1 | B4: Menu terlaris | C4: ='03_Data Bersih + Analisis'!L19 -> Es Kopi Susu
A5: 2 | B5: Total pendapatan minuman | C5: =Table2[[#Totals],[Minuman]] -> 2112000
A6: 3 | B6: Rata-rata penjualan per transaksi | C6: ='03_Data Bersih + Analisis'!O6 -> 57560
A9: INSIGHT & REKOMENDASI BISNIS
A11: No | B11: Temuan Data (Insight) | C11: Rekomendasi Aksi (Action Plan)
A12: 1 | B12: Es Kopi Susu Menjadi Kontributor Utama: Terjual 28 unit, menyumbang porsi terbesar pendapatan minuman. | C12: Jaga Stok & Loyalitas: Pastikan ketersediaan bahan baku "Es Kopi Susu" selalu aman. Buat program loyalitas (misal: Buy 5 Get 1 Free) khusus "Es Kopi Susu" untuk mempertahankan pelanggan.
A13: 2 | B13: Minuman Mendominasi: Pendapatan Minuman (Rp 2,112,000) sekitar 2,8x lipat Makanan (Rp 766,000). | C13: Strategi Bundling (Perlu Diuji Coba): Buat paket hemat (Kopi + Croissant) untuk "mengangkat" penjualan makanan yang masih rendah. (Catatan: Data saat ini belum menunjukkan pola pembelian bersamaan, sehingga promo ini perlu diuji efektivitasnya).
A14: 3 | B14: Rata-rata Belanja: Pelanggan belanja Rp 57,560 per transaksi. Pelanggan rata-rata membeli 2,7 gelas minuman per transaksi. | C14: Upselling: Tawarkan topping tambahan (extra shot / oat milk) atau camilan. (Contoh: Penambahan 1 item seharga Rp 7.500 dapat menaikkan rata-rata transaksi menjadi Rp 65.000+).
A15: 4 | B15: Metode Pembayaran Terbanyak: QRIS digunakan pada 22 dari 50 transaksi (44%). | C15: Digitalisasi: Pastikan jaringan QRIS lancar. Adakan kerja sama cashback dengan e-wallet untuk menarik pelanggan digital.
A16: 5 | B16: Menu Kurang Laku: Chocolate Cake lemah di unit (9) dan pendapatan (Rp 198.000). Chicken Sandwich unitnya rendah (9), tapi pendapatannya lebih sehat (Rp 288.000). | C16: Evaluasi & Pertahankan: Evaluasi rasa/porsi Chocolate Cake. Pertahankan Chicken Sandwich karena harganya yang tinggi (Rp 32.000) memberikan margin pendapatan yang lebih baik.
A17: 6 | B17: Fluktuasi Nilai per Order: Pendapatan harian berkisar Rp 224.000 sampai Rp 349.000. Karena jumlah order tetap 5 per hari, selisih pendapatan murni dipicu oleh nilai transaksi per pelanggan, bukan karena jumlah pelanggan. | C17: Pantau Nilai per Order: Pantau nilai transaksi harian dan uji apakah pola hari kerja vs akhir pekan konsisten pada data yang lebih panjang. Belum cukup bukti untuk mengambil keputusan terkait stok.
A19: ASUMSI & KETERBATASAN ANALISIS
A20: 1 | B20: Analisis didasarkan pada 50 transaksi selama 10 hari (1-10 Oktober 2026).
A21: 2 | B21: Satu baris pesanan (order) diasumsikan hanya berisi satu jenis menu, sehingga pola pembelian bersamaan (analisis keranjang belanja) tidak dapat dianalisis dari data ini.
A22: 3 | B22: Rekomendasi bisnis bersifat awal (preliminary) dan perlu divalidasi dengan data historis yang lebih panjang (minimal 1-3 bulan).

Sheet 07_Dokumentasi_Rumus
A1: Kolom Bantu & Tabel Pendukung
A2: No | B2: Tujuan/Kasus | C2: Rumus Excel | D2: Penjelasan Singkat
A3: 1 | B3: Menghitung Nilai Transaksi | C3: =E4*F4 | D3: Mengalikan harga dengan jumlah di baris yang sama.
A4: 2 | B4: Mengambil Daftar Menu Unik | C4: =UNIQUE(C4:C53) | D4: Mengambil daftar nama menu tanpa duplikat (Fungsi Excel 365/2021).
A5: 3 | B5: Menghitung Total Unit per Menu | C5: =SUMPRODUCT((C4:C53=$J12)*F4:F53) | D5: Menjumlahkan unit terjual khusus untuk menu yang disebut di sel J12.
A8: Kasus 1: Menu Terlaris (MAX, MIN, IF, Lookup)
A9: No | B9: Tujuan/Kasus | C9: Rumus Excel | D9: Penjelasan Singkat
A10: 4 | B10: Mencari Angka Tertinggi | C10: =MAX(K12:K19) | D10: Mencari nilai unit terjual paling banyak.
A11: 5 | B11: Mencari Angka Terendah | C11: =MIN(K12:K19) | D11: Mencari nilai unit terjual paling sedikit.
A12: 6 | B12: Menampilkan Nama Juara (IF) | C12: =IF(K12=MAX($K$12:$K$19), J12, "") | D12: Menampilkan nama menu JIKA nilai unitnya sama dengan MAX.
A13: 7 | B13: Mencari Nama Juara (INDEX-MATCH) | C13: =INDEX(J12:J19, MATCH(MAX(K12:K19), K12:K19, 0)) | D13: Mencari nama menu berdasarkan nilai MAX (metode klasik).
A14: 8 | B14: Mencari Nama Juara (XLOOKUP) | C14: =XLOOKUP(MAX(K12:K19), K12:K19, J12:J19) | D14: Mencari nama menu berdasarkan nilai MAX (metode modern).
A17: Kasus 2: Pendapatan Minuman (SUM, SUMIF, SUMIFS)
A18: No | B18: Tujuan/Kasus | C18: Rumus Excel | D18: Penjelasan Singkat
A19: 9 | B19: Total Pendapatan Kategori (SUMIF) | C19: =SUMIF(D4:D53, "Minuman", H4:H53) | D19: Menjumlahkan pendapatan HANYA untuk kategori Minuman.
A20: 10 | B20: Total Pendapatan Kategori (SUMIFS) | C20: =SUMIFS(H4:H53, D4:D53, "Minuman") | D20: Sama seperti di atas, tapi menggunakan SUMIFS (lebih disarankan).
A21: 11 | B21: Total Pendapatan via IF | C21: =IF(D4:D53="Minuman", H4:H53, 0) | D21: Menampilkan nilai transaksi JIKA kategori Minuman (butuh kolom bantu).
A22: 12 | B22: Logika AND/OR | C22: =IF(AND(D4="Minuman", G4="QRIS"), "Ya", "Tidak") | D22: Mengecek JIKA Minuman DAN dibayar pakai QRIS.
A25: Kasus 3: Rata-rata & Statistik (AVERAGE, COUNT, ROUND)
A26: No | B26: Tujuan/Kasus | C26: Rumus Excel | D26: Penjelasan Singkat
A27: 13 | B27: Rata-rata Nilai Transaksi | C27: =AVERAGE(H4:H53) | D27: Menghitung rata-rata uang yang dibelanjakan per transaksi.
A28: 14 | B28: Rata-rata Unit Terjual | C28: =AVERAGE(F4:F53) | D28: Menghitung rata-rata jumlah barang yang dibeli per transaksi (2,48).
A29: 15 | B29: Menghitung Data Angka | C29: =COUNT(H4:H53) | D29: Menghitung jumlah sel yang berisi angka (validasi data).
A30: 16 | B30: Menghitung Data Tidak Kosong | C30: =COUNTA(A4:A53) | D30: Menghitung jumlah baris transaksi (order ID).
A31: 17 | B31: Pembulatan Ribuan | C31: =ROUND(AVERAGE(H4:H53), -3) | D31: Membulatkan rata-rata ke ribuan terdekat (misal: 57.560 jadi 58.000).
A34: Analisis Tambahan (MINIFS, MAXIFS, AVERAGEIFS)
A35: No | B35: Tujuan/Kasus | C35: Rumus Excel | D35: Penjelasan Singkat
A36: 18 | B36: Nilai Terendah per Kategori | C36: =MINIFS(H4:H53, D4:D53, "Makanan") | D36: Mencari transaksi termurah khusus Makanan.
A37: 19 | B37: Nilai Tertinggi per Kategori | C37: =MAXIFS(H4:H53, D4:D53, "Minuman") | D37: Mencari transaksi termahal khusus Minuman.
A38: 20 | B38: Rata-rata per Kategori | C38: =AVERAGEIFS(H4:H53, D4:D53, "Makanan") | D38: Mencari rata-rata nilai transaksi khusus Minuman.
A39: 21 | B39: Rata-rata Manual (SUM/COUNT) | C39: =SUMIF(D4:D53,"Makanan",H4:H53)/COUNTIF(D4:D53,"Makanan") | D39: Menghitung rata-rata dengan membagi total nilai dengan jumlah transaksi.
A42: Dashboard & Data Interaktif
A43: No | B43: Tujuan/Kasus | C43: Rumus Excel | D43: Penjelasan Singkat
A44: 22 | B44: Mengambil Data dari Pivot (GETPIVOTDATA) | C44: =GETPIVOTDATA("Sum of nilai_transaksi",'04_Pivot_Table'!$D$1) | D44: Mengambil nilai spesifik dari PivotTable secara dinamis.
A45: 23 | B45: Mencegah Error saat Slicer Kosong (IFERROR) | C45: =IFERROR(GETPIVOTDATA(...), 0) | D45: Membungkus rumus GETPIVOTDATA agar menampilkan angka 0 (bukan #REF!) jika filter Slicer tidak menemukan data.
A46: 24 | B46: Membuat Tabel Ringkasan Dinamis | C46: =SUMIF($J$12:$J$19, J23, $K$12:$K$19) | D46: Menjumlahkan data berdasarkan nama menu yang dipilih pada dropdown di tabel ringkasan.
A49: Rujukan Lanjutan
A50: No | B50: Tujuan/Kasus | C50: Rumus Excel | D50: Penjelasan Singkat
A51: 25 | B51: Menautkan Jawaban ke Sheet Lain | C51: ='03_Data Bersih + Analisis'!O6 | D51: Mengambil nilai dari sheet lain (agar jawaban di laporan otomatis ter-update tanpa ketik manual).
A52: 26 | B52: Mengambil Total dari Tabel (Structured Ref) | C52: =Table2[[#Totals],[Minuman]] | D52: Mengambil angka dari baris "Total" spesifik pada kolom "Minuman" di tabel. Sangat berguna jika baris data bertambah.
